Workbook

Sheet Intro
F12: Name: | L12: Muhammad Haseeb
F15: Intern ID: | L15: 273
F18: Submitted To: | L18: Sir Abrar Amin
F21: Section: | L21: Switchgear Production

Sheet Dashboard
A1: HT Panels Final Aseembly Man Hour Analysis Dashboard | AE1: Absent Hours | AF1: =SUMIFS('Monthly Data'!$K:$K,'Monthly Data'!$A:$A,$D$4,'Monthly Data'!$B:$B,$I$4) -> 1328.4 | AH1: Month | AI1: Rework Hours
AE2: Gate Pass Hours | AF2: =SUMIFS('Monthly Data'!$L:$L,'Monthly Data'!$A:$A,$D$4,'Monthly Data'!$B:$B,$I$4) -> 442.8 | AH2: January | AI2: =SUMIFS('Reworking Data'!$I:$I,'Reworking Data'!$A:$A,AH2,'Reworking Data'!$B:$B,2026) -> 201
AE3: Breakdown Hours | AF3: =SUMIFS('Monthly Data'!$M:$M,'Monthly Data'!$A:$A,$D$4,'Monthly Data'!$B:$B,$I$4) -> 177.12 | AH3: February | AI3: =SUMIFS('Reworking Data'!$I:$I,'Reworking Data'!$A:$A,AH3,'Reworking Data'!$B:$B,2026) -> 1313
B4: Month | D4: January | G4: Year | I4: 2026 | L4: Panel Shops Performance Overview | AE4: Maintainence Hours | AF4: =SUMIFS('Monthly Data'!$N:$N,'Monthly Data'!$A:$A,$D$4,'Monthly Data'!$B:$B,$I$4) -> 10 | AH4: March | AI4: =SUMIFS('Reworking Data'!$I:$I,'Reworking Data'!$A:$A,AH4,'Reworking Data'!$B:$B,2026) -> 1073
AE5: Rework Hours | AF5: =SUMIFS('Monthly Data'!$P:$P,'Monthly Data'!$A:$A,$D$4,'Monthly Data'!$B:$B,$I$4) -> 75 | AH5: April | AI5: =SUMIFS('Reworking Data'!$I:$I,'Reworking Data'!$A:$A,AH5,'Reworking Data'!$B:$B,2026) -> 489.5
AH6: May | AI6: =SUMIFS('Reworking Data'!$I:$I,'Reworking Data'!$A:$A,AH6,'Reworking Data'!$B:$B,2026) -> 192.5
AH7: June | AI7: =SUMIFS('Reworking Data'!$I:$I,'Reworking Data'!$A:$A,AH7,'Reworking Data'!$B:$B,2026) -> 0
AH8: July | AI8: =SUMIFS('Reworking Data'!$I:$I,'Reworking Data'!$A:$A,AH8,'Reworking Data'!$B:$B,2026) -> 385
AB10: Product | AC10: total man hours | AD10: total quantity
AB11: INCOMING | AC11: =SUMIFS('Monthly Production'!$J:$J,'Monthly Production'!$F:$F,AB11,'Monthly Production'!$A:$A,$D$4,'Monthly Production'!$B:$B,$I$4) -> 1650 | AD11: =SUMIFS('Monthly Production'!$H:$H,'Monthly Production'!$F:$F,AB11,'Monthly Production'!$A:$A,$D$4,'Monthly Production'!$B:$B,$I$4) -> 10
AB12: Outgoing Panel | AC12: =SUMIFS('Monthly Production'!$J:$J,'Monthly Production'!$F:$F,AB12,'Monthly Production'!$A:$A,$D$4,'Monthly Production'!$B:$B,$I$4) -> 0 | AD12: =SUMIFS('Monthly Production'!$H:$H,'Monthly Production'!$F:$F,AB12,'Monthly Production'!$A:$A,$D$4,'Monthly Production'!$B:$B,$I$4) -> 0
AB13: Capacitor Control Panel | AC13: =SUMIFS('Monthly Production'!$J:$J,'Monthly Production'!$F:$F,AB13,'Monthly Production'!$A:$A,$D$4,'Monthly Production'!$B:$B,$I$4) -> 0 | AD13: =SUMIFS('Monthly Production'!$H:$H,'Monthly Production'!$F:$F,AB13,'Monthly Production'!$A:$A,$D$4,'Monthly Production'!$B:$B,$I$4) -> 0
AB14: Consumer Panel | AC14: =SUMIFS('Monthly Production'!$J:$J,'Monthly Production'!$F:$F,AB14,'Monthly Production'!$A:$A,$D$4,'Monthly Production'!$B:$B,$I$4) -> 145 | AD14: =SUMIFS('Monthly Production'!$H:$H,'Monthly Production'!$F:$F,AB14,'Monthly Production'!$A:$A,$D$4,'Monthly Production'!$B:$B,$I$4) -> 1
AB15: Owner | AC15: =SUMIFS('Monthly Production'!$J:$J,'Monthly Production'!$F:$F,AB15,'Monthly Production'!$A:$A,$D$4,'Monthly Production'!$B:$B,$I$4) -> 508 | AD15: =SUMIFS('Monthly Production'!$H:$H,'Monthly Production'!$F:$F,AB15,'Monthly Production'!$A:$A,$D$4,'Monthly Production'!$B:$B,$I$4) -> 4
AB16: Industrial | AC16: =SUMIFS('Monthly Production'!$J:$J,'Monthly Production'!$F:$F,AB16,'Monthly Production'!$A:$A,$D$4,'Monthly Production'!$B:$B,$I$4) -> 605 | AD16: =SUMIFS('Monthly Production'!$H:$H,'Monthly Production'!$F:$F,AB16,'Monthly Production'!$A:$A,$D$4,'Monthly Production'!$B:$B,$I$4) -> 5
AB17: Bus Coupler Panel | AC17: =SUMIFS('Monthly Production'!$J:$J,'Monthly Production'!$F:$F,AB17,'Monthly Production'!$A:$A,$D$4,'Monthly Production'!$B:$B,$I$4) -> 0 | AD17: =SUMIFS('Monthly Production'!$H:$H,'Monthly Production'!$F:$F,AB17,'Monthly Production'!$A:$A,$D$4,'Monthly Production'!$B:$B,$I$4) -> 0
AB18: K-Electric Type A | AC18: =SUMIFS('Monthly Production'!$J:$J,'Monthly Production'!$F:$F,AB18,'Monthly Production'!$A:$A,$D$4,'Monthly Production'!$B:$B,$I$4) -> 0 | AD18: =SUMIFS('Monthly Production'!$H:$H,'Monthly Production'!$F:$F,AB18,'Monthly Production'!$A:$A,$D$4,'Monthly Production'!$B:$B,$I$4) -> 0
AB19: K-Electric Type B | AC19: =SUMIFS('Monthly Production'!$J:$J,'Monthly Production'!$F:$F,AB19,'Monthly Production'!$A:$A,$D$4,'Monthly Production'!$B:$B,$I$4) -> 0 | AD19: =SUMIFS('Monthly Production'!$H:$H,'Monthly Production'!$F:$F,AB19,'Monthly Production'!$A:$A,$D$4,'Monthly Production'!$B:$B,$I$4) -> 0
AB20: Cassette Type-1 | AC20: =SUMIFS('Monthly Production'!$J:$J,'Monthly Production'!$F:$F,AB20,'Monthly Production'!$A:$A,$D$4,'Monthly Production'!$B:$B,$I$4) -> 980 | AD20: =SUMIFS('Monthly Production'!$H:$H,'Monthly Production'!$F:$F,AB20,'Monthly Production'!$A:$A,$D$4,'Monthly Production'!$B:$B,$I$4) -> 8
AB21: Cassette Type-2 | AC21: =SUMIFS('Monthly Production'!$J:$J,'Monthly Production'!$F:$F,AB21,'Monthly Production'!$A:$A,$D$4,'Monthly Production'!$B:$B,$I$4) -> 735 | AD21: =SUMIFS('Monthly Production'!$H:$H,'Monthly Production'!$F:$F,AB21,'Monthly Production'!$A:$A,$D$4,'Monthly Production'!$B:$B,$I$4) -> 6
AB22: LBS | AC22: =SUMIFS('Monthly Production'!$J:$J,'Monthly Production'!$F:$F,AB22,'Monthly Production'!$A:$A,$D$4,'Monthly Production'!$B:$B,$I$4) -> 195 | AD22: =SUMIFS('Monthly Production'!$H:$H,'Monthly Production'!$F:$F,AB22,'Monthly Production'!$A:$A,$D$4,'Monthly Production'!$B:$B,$I$4) -> 3
B66: =SUMIFS('Monthly Summary'!$C:$C,'Monthly Summary'!$A:$A,$D$4,'Monthly Summary'!$B:$B,$I$4) -> 9479.48
B68: =SUMIFS('Monthly Summary'!$D:$D,'Monthly Summary'!$A:$A,$D$4,'Monthly Summary'!$B:$B,$I$4) -> 5019
B69: =SUMIFS('Monthly Summary'!$E:$E,'Monthly Summary'!$A:$A,$D$4,'Monthly Summary'!$B:$B,$I$4) -> 4460.48
C71: =SUMIFS('Monthly Summary'!$F:$F,'Monthly Summary'!$A:$A,$D$4,'Monthly Summary'!$B:$B,$I$4) -> 0.52945942

Sheet Master Data
A1: Panel Welding Shop Man Hour's Calculation (Hour's) 2026
A2: Category | B2: Product | C2: Standard Man Hours
A3: MV PANEL | B3: INCOMING | C3: 22
A4: MV PANEL | B4: Outgoing Panel | C4: 16
A5: MV PANEL | B5: Capacitor Control Panel | C5: 16
A6: MV PANEL | B6: Consumer Panel | C6: 18
A7: MV PANEL | B7: Owner | C7: 16
A8: MV PANEL | B8: Industrial | C8: 20
A9: MV PANEL | B9: Bus Coupler Panel | C9: 58
A10: MV PANEL | B10: K-Electric Type A | C10: 58
A11: MV PANEL | B11: K-Electric Type B | C11: 58
A12: MV PANEL | B12: Cassette Type 1 | C12: 16
A13: MV PANEL | B13: Cassette Type 2 | C13: 16
A14: MV PANEL | B14: LBS | C14: 10

Sheet Monthly Data
A1: Monthly Data
A2: Month | B2: Years | C2: Employees | D2: Shift Hrs/Day | E2: Total Days | F2: Sundays | G2: Public Holidays | H2: Working Days | I2: Working Hrs /Employee | J2: Total Working Hrs | K2: Absent Hrs | L2: Gate Pass Hrs | M2: Breakdown Hrs | N2: Maintainence Hrs | O2: Overtime Hrs | P2: Rework Hrs | Q2: Net Available Hrs
A3: January | B3: 2026 | C3: 41 | D3: 8 | E3: =DAY(EOMONTH(DATE(B3,MATCH(A3,{"January","February","March","April","May","June","July","August","September","October","November","December"},0),1),0)) -> 31 | F3: {=SUMPRODUCT(--(WEEKDAY(DATE(B3,MATCH(A3,{"January","February","March","April","May","June","July","August","September","October","November","December"},0),ROW(INDIRECT("1:"&E3))),1)=1))} -> 4 | G3: 0 | H3: =E3-F3-G3 -> 27 | I3: =H3*D3 -> 216 | J3: =C3*I3 -> 8856 | K3: =J3*15% -> 1328.4 | L3: =J3*5% -> 442.8 | M3: =J3*2% -> 177.12 | N3: 10 | O3: =J3*30% -> 2656.8 | P3: 75 | Q3: =J3-K3-L3-M3-N3+O3-P3 -> 9479.48
A4: February | B4: 2026 | C4: 48 | D4: 8 | E4: =DAY(EOMONTH(DATE(B4,MATCH(A4,{"January","February","March","April","May","June","July","August","September","October","November","December"},0),1),0)) -> 28 | F4: {=SUMPRODUCT(--(WEEKDAY(DATE(B4,MATCH(A4,{"January","February","March","April","May","June","July","August","September","October","November","December"},0),ROW(INDIRECT("1:"&E4))),1)=1))} -> 4 | G4: 1 | H4: =E4-F4-G4 -> 23 | I4: =H4*D4 -> 184 | J4: =C4*I4 -> 8832 | K4: =J4*15% -> 1324.8 | L4: =J4*5% -> 441.6 | M4: =J4*2% -> 176.64 | N4: 12 | O4: =J4*30% -> 2649.6 | P4: 76 | Q4: =J4-K4-L4-M4-N4+O4-P4 -> 9450.56
A5: March | B5: 2026 | C5: 39 | D5: 8 | E5: =DAY(EOMONTH(DATE(B5,MATCH(A5,{"January","February","March","April","May","June","July","August","September","October","November","December"},0),1),0)) -> 31 | F5: {=SUMPRODUCT(--(WEEKDAY(DATE(B5,MATCH(A5,{"January","February","March","April","May","June","July","August","September","October","November","December"},0),ROW(INDIRECT("1:"&E5))),1)=1))} -> 5 | G5: 3 | H5: =E5-F5-G5 -> 23 | I5: =H5*D5 -> 184 | J5: =C5*I5 -> 7176 | K5: =J5*15% -> 1076.4 | L5: =J5*5% -> 358.8 | M5: =J5*2% -> 143.52 | N5: 8 | O5: =J5*30% -> 2152.8 | P5: 74 | Q5: =J5-K5-L5-M5-N5+O5-P5 -> 7668.08
A6: April | B6: 2026 | C6: 39 | D6: 8 | E6: =DAY(EOMONTH(DATE(B6,MATCH(A6,{"January","February","March","April","May","June","July","August","September","October","November","December"},0),1),0)) -> 30 | F6: {=SUMPRODUCT(--(WEEKDAY(DATE(B6,MATCH(A6,{"January","February","March","April","May","June","July","August","September","October","November","December"},0),ROW(INDIRECT("1:"&E6))),1)=1))} -> 4 | G6: 0 | H6: =E6-F6-G6 -> 26 | I6: =H6*D6 -> 208 | J6: =C6*I6 -> 8112 | K6: =J6*15% -> 1216.8 | L6: =J6*5% -> 405.6 | M6: =J6*2% -> 162.24 | N6: 6 | O6: =J6*30% -> 2433.6 | P6: 70 | Q6: =J6-K6-L6-M6-N6+O6-P6 -> 8684.96
A7: May | B7: 2026 | C7: 39 | D7: 8 | E7: =DAY(EOMONTH(DATE(B7,MATCH(A7,{"January","February","March","April","May","June","July","August","September","October","November","December"},0),1),0)) -> 31 | F7: {=SUMPRODUCT(--(WEEKDAY(DATE(B7,MATCH(A7,{"January","February","March","April","May","June","July","August","September","October","November","December"},0),ROW(INDIRECT("1:"&E7))),1)=1))} -> 5 | G7: 5 | H7: =E7-F7-G7 -> 21 | I7: =H7*D7 -> 168 | J7: =C7*I7 -> 6552 | K7: =J7*15% -> 982.8 | L7: =J7*5% -> 327.6 | M7: =J7*2% -> 131.04 | N7: 8 | O7: =J7*30% -> 1965.6 | P7: 72 | Q7: =J7-K7-L7-M7-N7+O7-P7 -> 6996.16
A8: June | B8: 2026 | C8: 42 | D8: 8 | E8: =DAY(EOMONTH(DATE(B8,MATCH(A8,{"January","February","March","April","May","June","July","August","September","October","November","December"},0),1),0)) -> 30 | F8: {=SUMPRODUCT(--(WEEKDAY(DATE(B8,MATCH(A8,{"January","February","March","April","May","June","July","August","September","October","November","December"},0),ROW(INDIRECT("1:"&E8))),1)=1))} -> 4 | G8: 2 | H8: =E8-F8-G8 -> 24 | I8: =H8*D8 -> 192 | J8: =C8*I8 -> 8064 | K8: =J8*15% -> 1209.6 | L8: =J8*5% -> 403.2 | M8: =J8*2% -> 161.28 | N8: 5 | O8: =J8*30% -> 2419.2 | P8: 72 | Q8: =J8-K8-L8-M8-N8+O8-P8 -> 8632.12
A9: July | B9: 2026 | C9: 55 | D9: 8 | E9: =DAY(EOMONTH(DATE(B9,MATCH(A9,{"January","February","March","April","May","June","July","August","September","October","November","December"},0),1),0)) -> 31 | F9: {=SUMPRODUCT(--(WEEKDAY(DATE(B9,MATCH(A9,{"January","February","March","April","May","June","July","August","September","October","November","December"},0),ROW(INDIRECT("1:"&E9))),1)=1))} -> 4 | G9: 0 | H9: =E9-F9-G9 -> 27 | I9: =H9*D9 -> 216 | J9: =C9*I9 -> 11880 | K9: =J9*15% -> 1782 | L9: =J9*5% -> 594 | M9: =J9*2% -> 237.6 | N9: 7 | O9: =J9*30% -> 3564 | P9: 73 | Q9: =J9-K9-L9-M9-N9+O9-P9 -> 12750.4
A10: August | B10: 2026 | C10: 30 | D10: 8 | E10: =DAY(EOMONTH(DATE(B10,MATCH(A10,{"January","February","March","April","May","June","July","August","September","October","November","December"},0),1),0)) -> 31 | F10: {=SUMPRODUCT(--(WEEKDAY(DATE(B10,MATCH(A10,{"January","February","March","April","May","June","July","August","September","October","November","December"},0),ROW(INDIRECT("1:"&E10))),1)=1))} -> 5 | G10: 2 | H10: =E10-F10-G10 -> 24 | I10: =H10*D10 -> 192 | J10: =C10*I10 -> 5760 | K10: =J10*15% -> 864 | L10: =J10*5% -> 288 | M10: =J10*2% -> 115.2 | N10: 8 | O10: =J10*30% -> 1728 | P10: 71 | Q10: =J10-K10-L10-M10-N10+O10-P10 -> 6141.8
A11: September | B11: 2026 | C11: 30 | D11: 8 | E11: =DAY(EOMONTH(DATE(B11,MATCH(A11,{"January","February","March","April","May","June","July","August","September","October","November","December"},0),1),0)) -> 30 | F11: {=SUMPRODUCT(--(WEEKDAY(DATE(B11,MATCH(A11,{"January","February","March","April","May","June","July","August","September","October","November","December"},0),ROW(INDIRECT("1:"&E11))),1)=1))} -> 4 | G11: 0 | H11: =E11-F11-G11 -> 26 | I11: =H11*D11 -> 208 | J11: =C11*I11 -> 6240 | K11: =J11*15% -> 936 | L11: =J11*5% -> 312 | M11: =J11*2% -> 124.8 | N11: 6 | O11: =J11*30% -> 1872 | P11: 72 | Q11: =J11-K11-L11-M11-N11+O11-P11 -> 6661.2
A12: October | B12: 2026 | C12: 26 | D12: 8 | E12: =DAY(EOMONTH(DATE(B12,MATCH(A12,{"January","February","March","April","May","June","July","August","September","October","November","December"},0),1),0)) -> 31 | F12: {=SUMPRODUCT(--(WEEKDAY(DATE(B12,MATCH(A12,{"January","February","March","April","May","June","July","August","September","October","November","December"},0),ROW(INDIRECT("1:"&E12))),1)=1))} -> 4 | G12: 0 | H12: =E12-F12-G12 -> 27 | I12: =H12*D12 -> 216 | J12: =C12*I12 -> 5616 | K12: =J12*15% -> 842.4 | L12: =J12*5% -> 280.8 | M12: =J12*2% -> 112.32 | N12: 7 | O12: =J12*30% -> 1684.8 | P12: 71 | Q12: =J12-K12-L12-M12-N12+O12-P12 -> 5987.28

Sheet Monthly Production
A1: Monthly Production
A2: Month | B2: Year | C2: FB NO | D2: Customer Name | E2: Description | F2: Panel Name | G2: Completion% | H2: Quantity | I2: Standard Man Hours/Products | J2: Total Man Hours
A3: January | B3: 2026 | C3: 1307141 | D3: GEPCO | E3: INCOMING PANELS. (31.5/40 MVA) | F3: INCOMING | G3: 1 | H3: 8 | I3: 165 | J3: =H3*I3 -> 1320
A4: January | B4: 2026 | C4: 1307074 | D4: FESCO | E4: INCOMING 31:40MVA PANEL | F4: INCOMING | G4: 1 | H4: 1 | I4: 165 | J4: =H4*I4 -> 165
A5: January | B5: 2026 | C5: 1307075 | D5: FESCO | E5: INCOMING 20:26 MVA PANEL | F5: INCOMING | G5: 1 | H5: 1 | I5: 165 | J5: =H5*I5 -> 165
A6: January | B6: 2026 | C6: 1307691 | D6: Boota Flour & Genereal Mill | E6: 11kV Wapda Metering Panel | F6: Industrial | G6: 1 | H6: 2 | I6: 112 | J6: =H6*I6 -> 224
A7: January | B7: 2026 | C7: 1307669 | D7: NATIONAL ENGINEERING & SCIENTIFIC COMISSION (NESCOM) | E7: 11kV LBS SWITCHBOARD | F7: LBS | G7: 1 | H7: 3 | I7: 65 | J7: =H7*I7 -> 195
A8: January | B8: 2026 | C8: 1307683 | D8: Kainat Enterprises (jv) | E8: 11KV T/F PROTECTION PANEL | F8: Owner | G8: 1 | H8: 1 | I8: 127 | J8: =H8*I8 -> 127
A9: January | B9: 2026 | C9: 1307689 | D9: Adamjee Engineering PVT | E9: 11 kV HT Switchboard (1 I/C + 2 O/G) | F9: Owner | G9: 1 | H9: 3 | I9: 127 | J9: =H9*I9 -> 381
A10: January | B10: 2026 | C10: 1307536 | D10: K-Electric (Formerly KESC)7700084675 | E10: 11 KV VCB PANEL CASSETTE TYPE 400/5A | F10: Cassette Type-2 | G10: 1 | H10: 6 | I10: 122.5 | J10: =H10*I10 -> 735
A11: January | B11: 2026 | C11: 1307532 | D11: K-Electric (Formerly KESC)7700084675 | E11: 11 KV VCB PANEL CASSETTE TYPE 100/5/5A | F11: Cassette Type-1 | G11: 1 | H11: 4 | I11: 122.5 | J11: =H11*I11 -> 490
A12: January | B12: 2026 | C12: 1307535 | D12: K-Electric (Formerly KESC)7700084675 | E12: 11 KV VCB PANEL CASSETTE TYPE 100/5/5A | F12: Cassette Type-1 | G12: 1 | H12: 4 | I12: 122.5 | J12: =H12*I12 -> 490
A13: January | B13: 2026 | C13: 1307703 | D13: STYLE STYROFOAM INDUSTRIES PVT LTD S.I.E. LAHORE. | E13: 11KV, 25KA MV PANEL (CONSUMER TYPE) | F13: Consumer Panel | G13: 1 | H13: 1 | I13: 145 | J13: =H13*I13 -> 145
A14: January | B14: 2026 | C14: 1307704, 05 | D14: STYLE STYROFOAM INDUSTRIES PVT LTD S.I.E. LAHORE. | E14: 11kV Wapda Metering Panel | F14: Industrial | G14: 1 | H14: 2 | I14: 127 | J14: =H14*I14 -> 254
A15: January | B15: 2026 | C15: 1307709 | D15: ARSHAD INDUSTRIES PVT LTD. LAHORE | E15: 11kV Wapda Metering Panel | F15: Industrial | G15: 1 | H15: 1 | I15: 127 | J15: =H15*I15 -> 127
A16: February | B16: 2026 | C16: 1307249 | D16: GEPCO | E16: INCOMING PANELS. (31.5/40 MVA) | F16: INCOMING | G16: 1 | H16: 4 | I16: 165 | J16: =H16*I16 -> 660
A17: February | B17: 2026 | C17: 1306950 | D17: GEPCO | E17: INCOMING PANELS. (20/26 MVA) | F17: INCOMING | G17: 1 | H17: 3 | I17: 165 | J17: =H17*I17 -> 495
A18: February | B18: 2026 | C18: 1307757 758 | D18: HADAYAT FOOD STUFFS INDUSTRIES (PVT) LTD MURIDKE | E18: 11kV Wapda Metering Panel | F18: Industrial | G18: 1 | H18: 2 | I18: 112 | J18: =H18*I18 -> 224
A19: February | B19: 2026 | C19: 130759 760 | D19: AKBARI AGRICHEM PRIVATE LIMITED SHEIKHUPURA. | E19: 11kV Wapda Metering Panel | F19: Industrial | G19: 1 | H19: 2 | I19: 112 | J19: =H19*I19 -> 224
A20: February | B20: 2026 | C20: 1307765 766 | D20: Jubilee Corporation for Rehman Medical Institute, Peshawar | E20: 11kV Wapda Metering Panel | F20: Industrial | G20: 1 | H20: 2 | I20: 112 | J20: =H20*I20 -> 224
A21: February | B21: 2026 | C21: 1307791 | D21: PAKISTAN STEEL FURNACE HARIPUR | E21: 11kV Wapda Metering Panel | F21: Industrial | G21: 1 | H21: 1 | I21: 112 | J21: =H21*I21 -> 112
A22: February | B22: 2026 | C22: 1307777 | D22: SITARA ENGINEERING & CONSTRUCTION COMPANY PESHAWAR | E22: 11kV Wapda Grid End Panel | F22: Consumer Panel | G22: 1 | H22: 1 | I22: 145 | J22: =H22*I22 -> 145
A23: February | B23: 2026 | C23: 1307710 | D23: Air Weapon Complex (AWC) | E23: 11kV Incoming Panel | F23: Owner | G23: 1 | H23: 2 | I23: 127 | J23: =H23*I23 -> 254
A24: February | B24: 2026 | C24: 1307711 | D24: Air Weapon Complex (AWC) | E24: 11kV Outgoing Panel | F24: Owner | G24: 1 | H24: 3 | I24: 127 | J24: =H24*I24 -> 381
A25: February | B25: 2026 | C25: 1307112 | D25: Patients Aid Foundation | E25: 11 kV Switchboard Panel (02 O/G & 01 Dummy Panel) | F25: Owner | G25: 1 | H25: 2 | I25: 127 | J25: =H25*I25 -> 254
A26: February | B26: 2026 | C26: 1307713 | D26: Patients Aid Foundation | E26: 11 kV HT Incoming cum Outgoing Panel | F26: Owner | G26: 1 | H26: 1 | I26: 127 | J26: =H26*I26 -> 127
A27: February | B27: 2026 | C27: 1307737 738 | D27: PARAGON CONSTRUCTORS (Project: Shaukat Khanum Memorial Cancer Hospital) | E27: 11kV MV 1 I/C 4 O/G SWITCHBOARD | F27: Owner | G27: 1 | H27: 4 | I27: 127 | J27: =H27*I27 -> 508
A28: February | B28: 2026 | C28: 1307361 | D28: S.B Enterprises | E28: 11 KV VCB PANEL CASSETTE TYPE 100/5A | F28: Cassette Type-2 | G28: 1 | H28: 1 | I28: 122.5 | J28: =H28*I28 -> 122.5
A29: February | B29: 2026 | C29: 1307793 | D29: S.B Enterprises | E29: 11 KV VCB PANEL CASSETTE TYPE 100/5A | F29: Cassette Type-2 | G29: 1 | H29: 1 | I29: 122.5 | J29: =H29*I29 -> 122.5
A30: February | B30: 2026 | C30: 1307361 | D30: S.B Enterprises | E30: 11 KV VCB PANEL CASSETTE TYPE 400/5A | F30: Cassette Type-2 | G30: 1 | H30: 2 | I30: 122.5 | J30: =H30*I30 -> 245
A31: February | B31: 2026 | C31: 1307782 | D31: Electric Gears Corporation | E31: 11KV 630A CT400/5 CASSETTE TYPE | F31: Cassette Type-2 | G31: 1 | H31: 2 | I31: 122.5 | J31: =H31*I31 -> 245
A32: February | B32: 2026 | C32: 1307781 | D32: Electric Gears Corporation | E32: 11KV 630A CT100/5/5 CASSETTE TYPE | F32: Cassette Type-1 | G32: 1 | H32: 1 | I32: 122.5 | J32: =H32*I32 -> 122.5
A33: February | B33: 2026 | C33: 1307762 | D33: Mehran Plastic Industries Pvt Ltd SITE Area Plant, Karachi | E33: 11 KV VCB PANEL CASSETTE TYPE 100/5/5A. | F33: Cassette Type-1 | G33: 1 | H33: 1 | I33: 122.5 | J33: =H33*I33 -> 122.5
A34: February | B34: 2026 | C34: 1307780 | D34: Pakistan Economic Zone Development | E34: 11KV 630A CT400/5/5 CASSETTE TYPE | F34: Cassette Type-1 | G34: 1 | H34: 1 | I34: 122.5 | J34: =H34*I34 -> 122.5
A35: February | B35: 2026 | C35: 1307779 | D35: Pakistan Economic Zone Development | E35: 11KV 630A CT400/5 CASSETTE TYPE | F35: Cassette Type-2 | G35: 1 | H35: 9 | I35: 122.5 | J35: =H35*I35 -> 1102.5
A36: February | B36: 2026 | C36: 1307785 | D36: Electric Gears Corporation Gandhara Autmobiles LTD | E36: 11KV 630A CT100/5/5 CASSETTE TYPE | F36: Cassette Type-1 | G36: 1 | H36: 1 | I36: 122.5 | J36: =H36*I36 -> 122.5
A37: February | B37: 2026 | C37: 1307786 | D37: Electric Gears Corporation Gandhara Autmobiles LTD | E37: 11KV 630A CT400/5/5 CASSETTE TYPE | F37: Cassette Type-1 | G37: 1 | H37: 1 | I37: 122.5 | J37: =H37*I37 -> 122.5
A38: February | B38: 2026 | C38: 1307787 | D38: Electric Gears Corporation Gandhara Autmobiles LTD | E38: 11KV 630A CT400/5 CASSETTE TYPE | F38: Cassette Type-2 | G38: 1 | H38: 1 | I38: 122.5 | J38: =H38*I38 -> 122.5
A39: February | B39: 2026 | C39: 1307769 | D39: K-Electric (Formerly KESC) 8200000941 | E39: 11KV 630A CT600/5/5 CASSETTE TYPE | F39: Cassette Type-1 | G39: 1 | H39: 1 | I39: 122.5 | J39: =H39*I39 -> 122.5
... A41: February | B41: 2026 | C41: 1307562 | D41: MEPCO | E41: 11KV, 25KA, OUTGOING PANELS. | F41: Outgoing Panel | G41: 1 | H41: 12 | I41: 126 | J41: =H41*I41 -> 1512
...

Sheet Reworking Data
A1: Reworking Data
A2: Month | B2: Year | C2: Customer Name | D2: Panel Name | E2: Panel Type | F2: Completion% | G2: Quantity | H2: Standard Man Hours/Products | I2: Total Man Hours
A3: January | B3: 2026 | C3: PEOPLE STEEL MILLS (PSM) | D3: Owner | E3: ELECTRICAL | F3: 1 | G3: 1 | H3: 47 | I3: =G3*H3 -> 47
A4: January | B4: 2026 | C4: K-Electric (Formerly KESC)7700084675 | D4: CASSETTE TYPE | E4: MACHNICAL | F4: 1 | G4: 2 | H4: 38.5 | I4: =G4*H4 -> 77
A5: January | B5: 2026 | C5: K-Electric (Formerly KESC)7700084675 | D5: CASSETTE TYPE | E5: MACHNICAL | F5: 1 | G5: 2 | H5: 38.5 | I5: =G5*H5 -> 77
A6: February | B6: 2026 | C6: PRIVATE VCB REPARING | D6: OWNER | E6: MACHNICAL | F6: 1 | G6: 2 | H6: 26 | I6: =G6*H6 -> 52
A7: February | B7: 2026 | C7: EARTHSWITCH PAD REPLACE | D7: K.ELECTRIC | E7: MACHNICAL | F7: 1 | G7: 11 | H7: 40.5 | I7: =G7*H7 -> 445.5
A8: February | B8: 2026 | C8: CT CHANGE | D8: K.ELECTRIC | E8: MACHNICAL | F8: 1 | G8: 15 | H8: 40.5 | I8: =G8*H8 -> 607.5
A9: February | B9: 2026 | C9: LABLE CHANGE | D9: OWNER | E9: MACHNICAL | F9: 1 | G9: 8 | H9: 26 | I9: =G9*H9 -> 208
A10: March | B10: 2026 | C10: INDUSTRIAL PANEL INSULATOR Replace | D10: Industrial | E10: MACHNICAL | F10: 1 | G10: 6 | H10: 26 | I10: =G10*H10 -> 156
A11: March | B11: 2026 | C11: EARTHSWITCH PAD REPLACE | D11: K.ELECTRIC | E11: MACHNICAL | F11: 1 | G11: 22 | H11: 40.5 | I11: =G11*H11 -> 891
A12: March | B12: 2026 | C12: OWNER PANEL BACKSHEET CHANGE | D12: OWNER | E12: MACHNICAL | F12: 1 | G12: 1 | H12: 26 | I12: =G12*H12 -> 26
A13: April | B13: 2026 | C13: INDUSTRIAL PANEL | D13: Industrial | E13: MACHNICAL | F13: 1 | G13: 2 | H13: 26 | I13: =G13*H13 -> 52
A14: April | B14: 2026 | C14: EARTHSWITCH PAD REPLACE | D14: K.ELECTRIC | E14: MACHNICAL | F14: 1 | G14: 5 | H14: 40.5 | I14: =G14*H14 -> 202.5
... A17: July | B17: 2026 | C17: K-ELECTRIC, KARACHI. | D17: CASSETTE TYPE | E17: MACHNICAL | F17: 1 | G17: 10 | H17: 38.5 | I17: =G17*H17 -> 385

Sheet Monthly Summary
A1: Monthly Summary
A2: Month | B2: Year | C2: Net Available Hours | D2: Production Hours | E2: Difference | F2: Efficiency (%)
A3: January | B3: 2026 | C3: =SUMIFS('Monthly Data'!$Q:$Q,'Monthly Data'!$A:$A,A3,'Monthly Data'!$B:$B,B3) -> 9479.48 | D3: =SUMIFS('Monthly Production'!$J:$J,'Monthly Production'!$A:$A,A3,'Monthly Production'!$B:$B,B3)+SUMIFS('Reworking Data'!$I:$I,'Reworking Data'!$A:$A,A3,'Reworking Data'!$B:$B,B3) -> 5019 | E3: =C3-D3 -> 4460.48 | F3: =IFERROR(D3/C3,0) -> 0.52945942
A4: February | B4: 2026 | C4: =SUMIFS('Monthly Data'!$Q:$Q,'Monthly Data'!$A:$A,A4,'Monthly Data'!$B:$B,B4) -> 9450.56 | D4: =SUMIFS('Monthly Production'!$J:$J,'Monthly Production'!$A:$A,A4,'Monthly Production'!$B:$B,B4)+SUMIFS('Reworking Data'!$I:$I,'Reworking Data'!$A:$A,A4,'Reworking Data'!$B:$B,B4) -> 9250.5 | E4: =C4-D4 -> 200.06 | F4: =IFERROR(D4/C4,0) -> 0.97883088
A5: March | B5: 2026 | C5: =SUMIFS('Monthly Data'!$Q:$Q,'Monthly Data'!$A:$A,A5,'Monthly Data'!$B:$B,B5) -> 7668.08 | D5: =SUMIFS('Monthly Production'!$J:$J,'Monthly Production'!$A:$A,A5,'Monthly Production'!$B:$B,B5)+SUMIFS('Reworking Data'!$I:$I,'Reworking Data'!$A:$A,A5,'Reworking Data'!$B:$B,B5) -> 5444.5 | E5: =C5-D5 -> 2223.58 | F5: =IFERROR(D5/C5,0) -> 0.71002128
A6: April | B6: 2026 | C6: =SUMIFS('Monthly Data'!$Q:$Q,'Monthly Data'!$A:$A,A6,'Monthly Data'!$B:$B,B6) -> 8684.96 | D6: =SUMIFS('Monthly Production'!$J:$J,'Monthly Production'!$A:$A,A6,'Monthly Production'!$B:$B,B6)+SUMIFS('Reworking Data'!$I:$I,'Reworking Data'!$A:$A,A6,'Reworking Data'!$B:$B,B6) -> 6576 | E6: =C6-D6 -> 2108.96 | F6: =IFERROR(D6/C6,0) -> 0.75717102
A7: May | B7: 2026 | C7: =SUMIFS('Monthly Data'!$Q:$Q,'Monthly Data'!$A:$A,A7,'Monthly Data'!$B:$B,B7) -> 6996.16 | D7: =SUMIFS('Monthly Production'!$J:$J,'Monthly Production'!$A:$A,A7,'Monthly Production'!$B:$B,B7)+SUMIFS('Reworking Data'!$I:$I,'Reworking Data'!$A:$A,A7,'Reworking Data'!$B:$B,B7) -> 5317.5 | E7: =C7-D7 -> 1678.66 | F7: =IFERROR(D7/C7,0) -> 0.7600598
A8: June | B8: 2026 | C8: =SUMIFS('Monthly Data'!$Q:$Q,'Monthly Data'!$A:$A,A8,'Monthly Data'!$B:$B,B8) -> 8632.12 | D8: =SUMIFS('Monthly Production'!$J:$J,'Monthly Production'!$A:$A,A8,'Monthly Production'!$B:$B,B8)+SUMIFS('Reworking Data'!$I:$I,'Reworking Data'!$A:$A,A8,'Reworking Data'!$B:$B,B8) -> 8412.5 | E8: =C8-D8 -> 219.62 | F8: =IFERROR(D8/C8,0) -> 0.97455781
A9: July | B9: 2026 | C9: =SUMIFS('Monthly Data'!$Q:$Q,'Monthly Data'!$A:$A,A9,'Monthly Data'!$B:$B,B9) -> 12750.4 | D9: =SUMIFS('Monthly Production'!$J:$J,'Monthly Production'!$A:$A,A9,'Monthly Production'!$B:$B,B9)+SUMIFS('Reworking Data'!$I:$I,'Reworking Data'!$A:$A,A9,'Reworking Data'!$B:$B,B9) -> 12436 | E9: =C9-D9 -> 314.4 | F9: =IFERROR(D9/C9,0) -> 0.97534195
